Workbook

Sheet Lienzos y espejos
A1: Basar Ojos Color Sol | Y1: Entradas totales de la semana | Z1: Importe de las Entradas Semanal | AO1: Importe en $
AA2: Basar Ojos Color Sol | AH2: Basar Ojos Color Sol
A5: INVENTARIO | F5: 46152 | G5: Semana del 11 al 16 de Mayo | U5: Venta Total | V5: Deuda | W5: Baja sem. | X5: F. 16/5 /26 | AO5: No | AP5: Total al costo | AQ5: Total a la Venta | AR5: Utilidad Total | AS5: $ en Mercancia
G6: D-10 | I6: L-11 | K6: M-12 | M6: Mi-13 | O6: J-14 | Q6: V-15 | S6: S-16 | AA6: =G5 -> Semana del 11 al 16 de Mayo | AH6: =AA6 -> Semana del 11 al 16 de Mayo
A7: No | B7: Costo | C7: Venta | D7: Gan. | E7: Producto | G7: Entra. | H7: Venta | I7: Entra. | J7: Venta | K7: Entra. | L7: Venta | M7: Entra. | N7: Venta | O7: Entra. | P7: Venta | Q7: Entra. | R7: Venta | S7: Entra. | T7: Venta | AA7: Domingo | AB7: Lunes | AC7: Martes | AD7: Miercoles | AE7: Jueves | AF7: Viernes | AG7: Sabado | AH7: Cuadre en efectivo de la Semana
E8: Lienzoz y Espejos | Z8: =Z9+Z10+Z11+Z12+Z13+Z14+Z15+Z16+Z17+Z19+Z20+Z21+Z22+Z23+Z24+Z25+Z26+Z27+Z30+Z31+Z32+Z33+Z34+Z35+Z36+Z37+Z38+Z39+Z40+Z41+Z42+Z43+Z44+Z45+Z47+Z48+Z49+Z50+Z51+Z52+Z53+Z54+Z55+Z56+Z57+Z58+Z59+Z60+Z61+Z62+Z63+Z64+Z65+Z66+Z67+Z68+Z69+Z70+Z71 -> 0 | AH8: Domingo | AI8: Lunes | AJ8: Martes | AK8: Miercoles | AL8: Jueves | AM8: Viernes | AN8: Sabado | AP8: =AP9+AP10+AP11+AP12+AP13+AP14+AP15+AP16+AP17+AP18+AP19+AP20+AP21+AP22+AP23+AP24+AP25+AP26+AP27+AP28+AP29+AP30+AP31+AP32+AP33+AP34+AP35+AP36+AP37+AP38+AP39+AP40+AP41+AP42+AP43+AP44+AP45+AP46+AP47+AP48+AP49+AP50+AP51+AP52+AP53+AP54+AP55+AP56+AP57+AP58+AP59+AP60+AP61+AP62+AP63+AP64+AP65+AP66+AP67+AP68+AP69+AP70+AP71+AP72+AP73+AP74+AP75+AP76+AP77+AP78+AP79+AP80+AP81+AP82+AP83+AP84+AP85+AP86+AP87+AP88+AP89+AP90+AP91+AP92+AP93+AP94+AP95+AP96+AP97+AP98+AP99+AP100+AP101+AP102+AP103+AP104+AP105+AP106+AP107+AP108+AP109+AP110+AP111+AP112+AP113+AP114+AP115+AP116+AP117+AP118+AP119+AP120+AP121+AP122+AP123+AP124+AP125+AP126+AP127+AP128+AP129+AP130+AP131+AP132+AP134+AP135+AP136+AP137+AP138+AP139+AP140+AP141+AP142+AP143+AP144+AP145+AP146+AP147+AP148+AP149+AP150+AP151+AP152+AP153+AP154+AP155+AP156+AP157+AP158+AP159+AP160+AP161+AP162+AP163+AP164+AP165+AP166+AP167+AP168+AP169+AP170+AP171+AP172+AP173+AP174+AP175+AP176+AP177+AP178+AP179+AP180+AP181+AP182+AP183+AP184+AP185+AP186+AP187+AP188+AP189+AP190+AP191+AP192+AP193+AP194+AP195+AP196+AP197+AP198+AP199+AP200+AP201+AP202+AP203+AP204+AP205+AP207+AP208+AP209+AP210+AP211+AP212+AP213+AP214+AP215+AP216+AP217+AP218+AP220+AP221+AP222+AP223+AP224+AP225+AP226+AP227+AP228+AP229+AP230+AP231+AP232+AP233+AP234+AP235+AP236+AP237+AP238+AP239+AP240+AP241+AP243+AP244+AP245+AP246+AP247+AP248+AP249+AP250+AP251+AP252+AP253+AP254+AP255+AP256+AP257+AP258+AP259+AP260+AP261+AP262+AP263+AP264+AP265+AP266+AP267+AP269+AP270+AP271+AP272+AP273+AP274+AP275+AP276+AP279+AP280+AP281+AP282+AP283+AP284+AP286+AP287+AP288+AP289+AP290+AP291+AP292+AP293+AP294+AP295+AP296+AP297+AP298+AP299+AP300+AP301+AP302+AP303+AP304+AP305+AP306+AP307+AP308+AP309+AP310+AP311+AP312+AP313+AP314+AP315+AP316+AP317+AP318+AP319+AP320+AP321+AP322+AP323+AP324+AP325+AP326+AP327+AP328+AP329+AP330+AP331+AP332+AP333+AP334+AP335+AP336+AP337+AP338+AP339+AP340+AP341+AP342+AP343+AP344+AP345+AP346+AP347+AP348+AP349+AP350+AP351+AP352+AP353+AP354+AP355+AP356+AP357+AP358+AP359+AP360+AP361+AP362+AP363+AP364+AP365+AP366+AP367+AP369+AP370+AP371+AP372+AP373+AP374+AP375+AP376+AP377+AP378+AP379+AP380+AP381+AP382+AP383+AP384+AP385+AP386+AP387+AP388+AP389+AP390+AP391+AP392+AP393+AP394+AP395+AP396+AP397+AP398+AP399+AP400+AP401+AP402+AP403+AP404+AP405+AP406+AP407+AP408+AP409+AP410+AP411+AP412+AP413+AP414+AP415+AP416+AP417+AP418+AP419+AP420+AP422+AP423+AP424+AP425+AP426+AP427+AP428+AP429+AP430+AP431+AP432+AP433+AP434+AP435+AP436+AP437+AP438+AP439+AP440+AP441+AP442+AP443+AP444+AP445+AP446+AP447+AP448+AP449+AP450+AP451+AP452+AP453+AP454+AP455+AP456+AP457+AP458+AP459+AP460+AP461+AP462+AP463+AP464+AP465+AP466+AP467+AP468+AP469+AP470+AP471+AP472+AP473+AP474 -> 0 | AQ8: =AQ9+AQ10+AQ11+AQ12+AQ13+AQ14+AQ15+AQ16+AQ17+AQ18+AQ19+AQ20+AQ21+AQ22+AQ23+AQ24+AQ25+AQ26+AQ27+AQ28+AQ29+AQ30+AQ31+AQ32+AQ33+AQ34+AQ35+AQ36+AQ37+AQ38+AQ39+AQ40+AQ41+AQ42+AQ43+AQ44+AQ45+AQ46+AQ47+AQ48+AQ49+AQ50+AQ51+AQ52+AQ53+AQ54+AQ55+AQ56+AQ57+AQ58+AQ59+AQ60+AQ61+AQ62+AQ63+AQ64+AQ65+AQ66+AQ67+AQ68+AQ69+AQ70+AQ71+AQ72+AQ73+AQ74+AQ75+AQ76+AQ77+AQ78+AQ79+AQ80+AQ81+AQ82+AQ83+AQ84+AQ85+AQ86+AQ87+AQ88+AQ89+AQ90+AQ91+AQ92+AQ93+AQ94+AQ95+AQ96+AQ97+AQ98+AQ99+AQ100+AQ101+AQ102+AQ103+AQ104+AQ105+AQ106+AQ107+AQ108+AQ109+AQ110+AQ111+AQ112+AQ113+AQ114+AQ115+AQ116+AQ117+AQ118+AQ119+AQ120+AQ121+AQ122+AQ123+AQ124+AQ125+AQ126+AQ127+AQ128+AQ129+AQ130+AQ131+AQ132+AQ133+AQ134+AQ135+AQ136+AQ137+AQ138+AQ139+AQ140+AQ141+AQ142+AQ143+AQ144+AQ145+AQ146+AQ147+AQ148+AQ149+AQ150+AQ151+AQ152+AQ153+AQ154+AQ155+AQ156+AQ157+AQ158+AQ159+AQ160+AQ161+AQ162+AQ163+AQ164+AQ165+AQ166+AQ167+AQ168+AQ169+AQ170+AQ171+AQ172+AQ173+AQ174+AQ175+AQ176+AQ177+AQ178+AQ179+AQ180+AQ181+AQ182+AQ183+AQ184+AQ185+AQ186+AQ187+AQ188+AQ189+AQ190+AQ191+AQ192+AQ193+AQ194+AQ195+AQ196+AQ197+AQ198+AQ199+AQ200+AQ201+AQ202+AQ203+AQ204+AQ205+AQ206+AQ207+AQ208+AQ209+AQ210+AQ211+AQ212+AQ213+AQ214+AQ215+AQ216+AQ217+AQ218+AQ219+AQ220+AQ221+AQ222+AQ223+AQ224+AQ225+AQ226+AQ227+AQ228+AQ229+AQ230+AQ231+AQ232+AQ233+AQ234+AQ235+AQ236+AQ237+AQ238+AQ239+AQ240+AQ241+AQ242+AQ243+AQ244+AQ245+AQ246+AQ247+AQ248+AQ249+AQ250+AQ251+AQ252+AQ253+AQ254+AQ255+AQ256+AQ257+AQ258+AQ259+AQ260+AQ261+AQ262+AQ263+AQ264+AQ265+AQ266+AQ267+AQ268+AQ269+AQ270+AQ271+AQ272+AQ273+AQ274+AQ275+AQ276+AQ277+AQ278+AQ279+AQ280+AQ281+AQ282+AQ283+AQ284+AQ285+AQ286+AQ287+AQ288+AQ289+AQ290+AQ291+AQ292+AQ293+AQ294+AQ295+AQ296+AQ297+AQ298+AQ299+AQ300+AQ301+AQ302+AQ303+AQ304+AQ305+AQ306+AQ307+AQ308+AQ309+AQ310+AQ311+AQ312+AQ313+AQ314+AQ315+AQ316+AQ317+AQ318+AQ319+AQ320+AQ321+AQ322+AQ323+AQ324+AQ325+AQ326+AQ327+AQ328+AQ329+AQ330+AQ331+AQ332+AQ333+AQ334+AQ335+AQ336+AQ337+AQ338+AQ339+AQ340+AQ341+AQ342+AQ343+AQ344+AQ345+AQ346+AQ347+AQ348+AQ349+AQ350+AQ351+AQ352+AQ353+AQ354+AQ355+AQ356+AQ357+AQ358+AQ359+AQ360+AQ361+AQ362+AQ363+AQ364+AQ365+AQ366+AQ367+AQ368+AQ369+AQ370+AQ371+AQ372+AQ373+AQ374+AQ375+AQ376+AQ377+AQ378+AQ379+AQ380+AQ381+AQ382+AQ383+AQ384+AQ385+AQ386+AQ387+AQ388+AQ389+AQ390+AQ391+AQ392+AQ393+AQ394+AQ395+AQ396+AQ397+AQ398+AQ399+AQ400+AQ401+AQ402+AQ403+AQ404+AQ405+AQ406+AQ407+AQ408+AQ409+AQ410+AQ411+AQ412+AQ413+AQ414+AQ415+AQ416+AQ417+AQ418+AQ419+AQ420+AQ421+AQ422+AQ423+AQ424+AQ425+AQ426+AQ427+AQ428+AQ429+AQ430+AQ431+AQ432+AQ433+AQ434+AQ435+AQ436+AQ437+AQ438+AQ439+AQ440+AQ441+AQ442+AQ443+AQ444+AQ445+AQ446+AQ447+AQ448+AQ449+AQ450+AQ451+AQ452+AQ453+AQ454+AQ455+AQ456+AQ457+AQ458+AQ459+AQ460+AQ461+AQ462+AQ463+AQ464+AQ465+AQ466+AQ467+AQ468+AQ469+AQ470+AQ471+AQ472+AQ473+AQ474+AQ475+AQ476+AQ477+AQ478+AQ479+AQ480+AQ481+AQ482+AQ483+AQ484+AQ485+AQ486+AQ487+AQ488+AQ489+AQ490+AQ491+AQ492+AQ493+AQ494+AQ495+AQ496+AQ497+AQ498+AQ499+AQ500+AQ501+AQ502+AQ503+AQ504+AQ505+AQ506+AQ507+AQ508+AQ509+AQ510+AQ511+AQ512+AQ513+AQ514+AQ515+AQ516+AQ517+AQ518+AQ519+AQ520+AQ521+AQ522+AQ523+AQ524+AQ525+AQ526+AQ527+AQ528+AQ529+AQ530+AQ531+AQ532+AQ533+AQ534+AQ535+AQ536+AQ537+AQ538+AQ539+AQ540+AQ541+AQ542+AQ543+AQ544+AQ545+AQ546+AQ547+AQ548+AQ549+AQ550+AQ551+AQ552+AQ553+AQ554+AQ555+AQ556 -> 0 | AR8: =AQ8-AP8 -> 0 | AS8: =AS9+AS10+AS11+AS12+AS13+AS14+AS15+AS16+AS17+AS18+AS19+AS20+AS21+AS22+AS23+AS24+AS25+AS26+AS27+AS28+AS29+AS30+AS31+AS32+AS33+AS34+AS35+AS36+AS37+AS38+AS39+AS40+AS41+AS42+AS43+AS44+AS45+AS46+AS47+AS48+AS49+AS50+AS51+AS52+AS53+AS54+AS55+AS56+AS57+AS58+AS59+AS60+AS61+AS62+AS63+AS64+AS65+AS66+AS67+AS68+AS69+AS70+AS71+AS72+AS73+AS74+AS75+AS76+AS77+AS78+AS79+AS80+AS81+AS82+AS83+AS84+AS85+AS86+AS87+AS88+AS89+AS90+AS91+AS92+AS93+AS94+AS95+AS96+AS97+AS98+AS99+AS100+AS101+AS102+AS103+AS104+AS105+AS106+AS107+AS108+AS109+AS110+AS111+AS112+AS113+AS114+AS115+AS116+AS117+AS118+AS119+AS120+AS121+AS122+AS123+AS124+AS125+AS126+AS127+AS128+AS129+AS130+AS131+AS132+AS133+AS134+AS135+AS136+AS137+AS138+AS139+AS140+AS141+AS142+AS143+AS144+AS145+AS146+AS147+AS148+AS149+AS150+AS151+AS152+AS153+AS154+AS155+AS156+AS157+AS158+AS159+AS160+AS161+AS162+AS163+AS164+AS165+AS166+AS167+AS168+AS169+AS170+AS171+AS172+AS173+AS174+AS175+AS176+AS177+AS178+AS179+AS180+AS181+AS182+AS183+AS184+AS185+AS186+AS187+AS188+AS189+AS190+AS191+AS192+AS193+AS194+AS195+AS196+AS197+AS198+AS199+AS200+AS201+AS202+AS203+AS204+AS205+AS207+AS208+AS209+AS210+AS211+AS212+AS213+AS214+AS215+AS216+AS217+AS218+AS220+AS221+AS222+AS223+AS224+AS225+AS226+AS227+AS228+AS229+AS230+AS231+AS232+AS233+AS234+AS235+AS236+AS237+AS238+AS239+AS240+AS241+AS243+AS244+AS245+AS246+AS247+AS248+AS249+AS250+AS251+AS252+AS253+AS254+AS255+AS256+AS257+AS258+AS259+AS260+AS261+AS262+AS263+AS264+AS265+AS266+AS267+AS269+AS270+AS271+AS272+AS273+AS274+AS275+AS276+AS279+AS280+AS281+AS282+AS283+AS284+AS286+AS287+AS288+AS289+AS290+AS291+AS292+AS293+AS294+AS295+AS296+AS297+AS298+AS299+AS300+AS301+AS302+AS303+AS304+AS305+AS306+AS307+AS308+AS309+AS310+AS311+AS312+AS313+AS314+AS315+AS316+AS317+AS318+AS319+AS320+AS321+AS322+AS323+AS324+AS325+AS326+AS327+AS328+AS329+AS330+AS331+AS332+AS333+AS334+AS335+AS336+AS337+AS338+AS339+AS340+AS341+AS342+AS343+AS344+AS345+AS346+AS347+AS348+AS349+AS350+AS351+AS352+AS353+AS354+AS355+AS356+AS357+AS358+AS359+AS360+AS361+AS362+AS363+AS364+AS365+AS366+AS367+AS369+AS370+AS371+AS372+AS373+AS374+AS375+AS376+AS377+AS378+AS379+AS380+AS381+AS382+AS383+AS384+AS385+AS386+AS387+AS388+AS389+AS390+AS391+AS392+AS393+AS394+AS395+AS396+AS397+AS398+AS399+AS400+AS401+AS402+AS403+AS404+AS405+AS406+AS407+AS408+AS409+AS410+AS411+AS412+AS413+AS414+AS415+AS416+AS417+AS418+AS419+AS420+AS422+AS423+AS424+AS425+AS426+AS427+AS428+AS429+AS430+AS431+AS432+AS433+AS434+AS435+AS436+AS437+AS438+AS439+AS440+AS441+AS442+AS443+AS444+AS445+AS446+AS447+AS448+AS449+AS450+AS451+AS452+AS453+AS454+AS455+AS456+AS457+AS458+AS459+AS460+AS461+AS462+AS463+AS464+AS465+AS466+AS467+AS468+AS469+AS470+AS471+AS472+AS473+AS474 -> 15000
A9: 1 | B9: 1300 | C9: 2000 | D9: 700 | E9: Lona Chicas | F9: 3 | U9: =H9+J9+L9+N9+P9+R9+T9 -> 0 | X9: =F9+G9+I9+K9+M9+O9+Q9+S9-H9-J9-L9-N9-P9-R9-T9-V9-W9 -> 3 | Y9: =G9+I9+K9+M9+O9+Q9+S9 -> 0 | Z9: =Y9*B9 -> 0 | AA9: =H9*C9 -> 0 | AB9: =J9*C9 -> 0 | AC9: =L9*C9 -> 0 | AD9: =N9*C9 -> 0 | AE9: =P9*C9 -> 0 | AF9: =R9*C9 -> 0 | AG9: =T9*C9 -> 0 | AH9: =AA9+AA10+AA11+AA12+AA13+AA14+AA15+AA16+AA17+AA18+AA19+AA20+AA21+AA22+AA23+AA24+AA25+AA26+AA27+AA28+AA30+AA31+AA32+AA33+AA34+AA35+AA36+AA37+AA38+AA39+AA40+AA41+AA42+AA43+AA44+AA45+AA47+AA48+AA49+AA50+AA51+AA52+AA53+AA54+AA55+AA56+AA57+AA58+AA59+AA60+AA61+AA62+AA63+AA64+AA65+AA66+AA67+AA68+AA69+AA70+AA71+AA72+AA73+AA74+AA75+AA76+AA77+AA78+AA79+AA80+AA81+AA82+AA83+AA84+AA85+AA86+AA87+AA88+AA89+AA90+AA91+AA92+AA93+AA94+AA95+AA96+AA97+AA98+AA99+AA100+AA101+AA102+AA103+AA104+AA105+AA106+AA107+AA108+AA109+AA110+AA111+AA112+AA113+AA114+AA115+AA116+AA117+AA118+AA119+AA120+AA121+AA122+AA123+AA124+AA125+AA126+AA127+AA128+AA129+AA130+AA131+AA132+AA133+AA134+AA135+AA136+AA137+AA138+AA139+AA140+AA141+AA142+AA143+AA144+AA145+AA146+AA147+AA148+AA149+AA150+AA151+AA152+AA153+AA154+AA155+AA156+AA157+AA158+AA159+AA160+AA161+AA162+AA163+AA164+AA165+AA166+AA167+AA168+AA169+AA170+AA171+AA172+AA173+AA174+AA175+AA176+AA177+AA178+AA179+AA180+AA181+AA182+AA183+AA184+AA185+AA186+AA187+AA188+AA189+AA190+AA191+AA192+AA193+AA194+AA195+AA196+AA197+AA198+AA199+AA200+AA201+AA202+AA203+AA204+AA205+AA206+AA207+AA208+AA209+AA210+AA211+AA212+AA213+AA214+AA215+AA216+AA217+AA218+AA219+AA220+AA221+AA222+AA223+AA224+AA225+AA226+AA227+AA228+AA229+AA230+AA231+AA232+AA233+AA234+AA235+AA236+AA237+AA238+AA239+AA240+AA241+AA242+AA243+AA244+AA245+AA246+AA247+AA248+AA249+AA250+AA251+AA252+AA253+AA254+AA255+AA256+AA257+AA258+AA259+AA260+AA261+AA262+AA263+AA264+AA265+AA266+AA267+AA268+AA269+AA270+AA271+AA272+AA273+AA274+AA275+AA276+AA277+AA278+AA279+AA280+AA281+AA282+AA283+AA284+AA285+AA286+AA287+AA288+AA289+AA290+AA291+AA292+AA293+AA294+AA295+AA296+AA297+AA298+AA299+AA300+AA301+AA302+AA303+AA304+AA305+AA306+AA307+AA308+AA309+AA310+AA311+AA312+AA313+AA314+AA315+AA316+AA317+AA318+AA319+AA320+AA321+AA322+AA323+AA324+AA325+AA326+AA327+AA328+AA329+AA330+AA331+AA332+AA333+AA334+AA335+AA336+AA337+AA338+AA339+AA340+AA341+AA342+AA343+AA344+AA345+AA346+AA347+AA348+AA349+AA350+AA351+AA352+AA353+AA354+AA355+AA356+AA357+AA358+AA359+AA360+AA361+AA362+AA363+AA364+AA365+AA366+AA367+AA368+AA369+AA370+AA371+AA372+AA373+AA374+AA375+AA376+AA377+AA378+AA379+AA380+AA381+AA382+AA383+AA384+AA385+AA386+AA387+AA388+AA389+AA390+AA391+AA392+AA393+AA394+AA395+AA396+AA397+AA398+AA399+AA400+AA401+AA402+AA403+AA404+AA405+AA406+AA407+AA408+AA409+AA410+AA411+AA412+AA413+AA414+AA415+AA416+AA417+AA418+AA419+AA420+AA421+AA422+AA423+AA424+AA425+AA426+AA427+AA428+AA429+AA430+AA431+AA432+AA433+AA434+AA435+AA436+AA437+AA438+AA439+AA440+AA441+AA442+AA443+AA444+AA445+AA446+AA447+AA448+AA449+AA450+AA451+AA452+AA453+AA454+AA455+AA456+AA457+AA458+AA459+AA460+AA461+AA462+AA463+AA464+AA465+AA466+AA467+AA468+AA469+AA470+AA471+AA472+AA473+AA474+AA475+AA476+AA477+AA478+AA479+AA480+AA481+AA482+AA483+AA484+AA485+AA486+AA487+AA488+AA489+AA490+AA491+AA492+AA493+AA494+AA495+AA496+AA497+AA498+AA499+AA500+AA501+AA502+AA503+AA504+AA505+AA506+AA507+AA508+AA509+AA510+AA511+AA512+AA513+AA514+AA515+AA516+AA517+AA518+AA519+AA520+AA521+AA522+AA523+AA524+AA525+AA526+AA527+AA528+AA529+AA530+AA531+AA532+AA533+AA534+AA535+AA536+AA537+AA538+AA539+AA540+AA541+AA542+AA543+AA544+AA545+AA546+AA547+AA548+AA549+AA550+AA551+AA552+AA553+AA554+AA555+AA556+AA557+AA558+AA559+AA560+AA561+AA562+AA563 -> 0 | AI9: =AB9+AB10+AB11+AB12+AB13+AB14+AB15+AB16+AB17+AB18+AB19+AB20+AB21+AB22+AB23+AB24+AB25+AB26+AB27+AB28+AB29+AB30+AB31+AB32+AB33+AB34+AB35+AB36+AB37+AB38+AB39+AB40+AB41+AB42+AB43+AB44+AB45+AB46+AB47+AB48+AB49+AB50+AB51+AB52+AB53+AB54+AB55+AB56+AB57+AB58+AB59+AB60+AB61+AB62+AB63+AB64+AB65+AB66+AB67+AB68+AB69+AB70+AB71+AB72+AB73+AB74+AB75+AB76+AB77+AB78+AB79+AB80+AB81+AB82+AB83+AB84+AB85+AB86+AB87+AB88+AB89+AB90+AB91+AB92+AB93+AB94+AB95+AB96+AB97+AB98+AB99+AB100+AB101+AB102+AB103+AB104+AB105+AB106+AB107+AB108+AB109+AB110+AB111+AB112+AB113+AB114+AB115+AB116+AB117+AB118+AB119+AB120+AB121+AB122+AB123+AB124+AB125+AB126+AB127+AB128+AB129+AB130+AB131+AB132+AB133+AB134+AB135+AB136+AB137+AB138+AB139+AB140+AB141+AB142+AB143+AB144+AB145+AB146+AB147+AB148+AB149+AB150+AB151+AB152+AB153+AB154+AB155+AB156+AB157+AB158+AB159+AB160+AB161+AB162+AB163+AB164+AB165+AB166+AB167+AB168+AB169+AB170+AB171+AB172+AB173+AB174+AB175+AB176+AB177+AB178+AB179+AB180+AB181+AB182+AB183+AB184+AB185+AB186+AB187+AB188+AB189+AB190+AB191+AB192+AB193+AB194+AB195+AB196+AB197+AB198+AB199+AB200+AB201+AB202+AB203+AB204+AB205+AB206+AB207+AB208+AB209+AB210+AB211+AB212+AB213+AB214+AB215+AB216+AB217+AB218+AB219+AB220+AB221+AB222+AB223+AB224+AB225+AB226+AB227+AB228+AB229+AB230+AB231+AB232+AB233+AB234+AB235+AB236+AB237+AB238+AB239+AB240+AB241+AB242+AB243+AB244+AB245+AB246+AB247+AB248+AB249+AB250+AB251+AB252+AB253+AB254+AB255+AB256+AB257+AB258+AB259+AB260+AB261+AB262+AB263+AB264+AB265+AB266+AB267+AB268+AB269+AB270+AB271+AB272+AB273+AB274+AB275+AB276+AB277+AB278+AB279+AB280+AB281+AB282+AB283+AB284+AB285+AB286+AB287+AB288+AB289+AB290+AB291+AB292+AB293+AB294+AB295+AB296+AB297+AB298+AB299+AB300+AB301+AB302+AB303+AB304+AB305+AB306+AB307+AB308+AB309+AB310+AB311+AB312+AB313+AB314+AB315+AB316+AB317+AB318+AB319+AB320+AB321+AB322+AB323+AB324+AB325+AB326+AB327+AB328+AB329+AB330+AB331+AB332+AB333+AB334+AB335+AB336+AB337+AB338+AB339+AB340+AB341+AB342+AB343+AB344+AB345+AB346+AB347+AB348+AB349+AB350+AB351+AB352+AB353+AB354+AB355+AB356+AB357+AB358+AB359+AB360+AB361+AB362+AB363+AB364+AB365+AB366+AB367+AB368+AB369+AB370+AB371+AB372+AB373+AB374+AB375+AB376+AB377+AB378+AB379+AB380+AB381+AB382+AB383+AB384+AB385+AB386+AB387+AB388+AB389+AB390+AB391+AB392+AB393+AB394+AB395+AB396+AB397+AB398+AB399+AB400+AB401+AB402+AB403+AB404+AB405+AB406+AB407+AB408+AB409+AB410+AB411+AB412+AB413+AB414+AB415+AB416+AB417+AB418+AB419+AB420+AB421+AB422+AB423+AB424+AB425+AB426+AB427+AB428+AB429+AB430+AB431+AB432+AB433+AB434+AB435+AB436+AB437+AB438+AB439+AB440+AB441+AB442+AB443+AB444+AB445+AB446+AB447+AB448+AB449+AB450+AB451+AB452+AB453+AB454+AB455+AB456+AB457+AB458+AB459+AB460+AB461+AB462+AB463+AB464+AB465+AB466+AB467+AB468+AB469+AB470+AB471+AB472+AB473+AB474+AB475+AB476+AB477+AB478+AB479+AB480+AB481+AB482+AB483+AB484+AB485+AB486+AB487+AB488+AB489+AB490+AB491+AB492+AB493+AB494+AB495+AB496+AB497+AB498+AB499+AB500+AB501+AB502+AB503+AB504+AB505+AB506+AB507+AB508+AB509+AB510+AB511+AB512+AB513+AB514+AB515+AB516+AB517+AB518+AB519+AB520+AB521+AB522+AB523+AB524+AB525+AB526+AB527+AB528+AB529+AB530+AB531+AB532+AB533+AB534+AB535+AB536+AB537+AB538+AB539+AB540+AB541+AB542+AB543+AB544+AB545+AB546+AB547+AB548+AB549+AB550+AB551+AB552+AB553+AB554+AB555+AB556+AB557+AB558+AB559+AB560+AB561+AB562+AB563 -> 0 | AJ9: =AC9+AC10+AC11+AC12+AC13+AC14+AC15+AC16+AC17+AC18+AC19+AC20+AC21+AC22+AC23+AC24+AC25+AC26+AC27+AC28+AC29+AC30+AC31+AC32+AC33+AC34+AC35+AC36+AC37+AC38+AC39+AC40+AC41+AC42+AC43+AC44+AC45+AC46+AC47+AC48+AC49+AC50+AC51+AC52+AC53+AC54+AC55+AC56+AC57+AC58+AC59+AC60+AC61+AC62+AC63+AC64+AC65+AC66+AC67+AC68+AC69+AC70+AC71+AC72+AC73+AC74+AC75+AC76+AC77+AC78+AC79+AC80+AC81+AC82+AC83+AC84+AC85+AC86+AC87+AC88+AC89+AC90+AC91+AC92+AC93+AC94+AC95+AC96+AC97+AC98+AC99+AC100+AC101+AC102+AC103+AC104+AC105+AC106+AC107+AC108+AC109+AC110+AC111+AC112+AC113+AC114+AC115+AC116+AC117+AC118+AC119+AC120+AC121+AC122+AC123+AC124+AC125+AC126+AC127+AC128+AC129+AC130+AC131+AC132+AC133+AC134+AC135+AC136+AC137+AC138+AC139+AC140+AC141+AC142+AC143+AC144+AC145+AC146+AC147+AC148+AC149+AC150+AC151+AC152+AC153+AC154+AC155+AC156+AC157+AC158+AC159+AC160+AC161+AC162+AC163+AC164+AC165+AC166+AC167+AC168+AC169+AC170+AC171+AC172+AC173+AC174+AC175+AC176+AC177+AC178+AC179+AC180+AC181+AC182+AC183+AC184+AC185+AC186+AC187+AC188+AC189+AC190+AC191+AC192+AC193+AC194+AC195+AC196+AC197+AC198+AC199+AC200+AC201+AC202+AC203+AC204+AC205+AC206+AC207+AC208+AC209+AC210+AC211+AC212+AC213+AC214+AC215+AC216+AC217+AC218+AC219+AC220+AC221+AC222+AC223+AC224+AC225+AC226+AC227+AC228+AC229+AC230+AC231+AC232+AC233+AC234+AC235+AC236+AC237+AC238+AC239+AC240+AC241+AC242+AC243+AC244+AC245+AC246+AC247+AC248+AC249+AC250+AC251+AC252+AC253+AC254+AC255+AC256+AC257+AC258+AC259+AC260+AC261+AC262+AC263+AC264+AC265+AC266+AC267+AC268+AC269+AC270+AC271+AC272+AC273+AC274+AC275+AC276+AC277+AC278+AC279+AC280+AC281+AC282+AC283+AC284+AC285+AC286+AC287+AC288+AC289+AC290+AC291+AC292+AC293+AC294+AC295+AC296+AC297+AC298+AC299+AC300+AC301+AC302+AC303+AC304+AC305+AC306+AC307+AC308+AC309+AC310+AC311+AC312+AC313+AC314+AC315+AC316+AC317+AC318+AC319+AC320+AC321+AC322+AC323+AC324+AC325+AC326+AC327+AC328+AC329+AC330+AC331+AC332+AC333+AC334+AC335+AC336+AC337+AC338+AC339+AC340+AC341+AC342+AC343+AC344+AC345+AC346+AC347+AC348+AC349+AC350+AC351+AC352+AC353+AC354+AC355+AC356+AC357+AC358+AC359+AC360+AC361+AC362+AC363+AC364+AC365+AC366+AC367+AC368+AC369+AC370+AC371+AC372+AC373+AC374+AC375+AC376+AC377+AC378+AC379+AC380+AC381+AC382+AC383+AC384+AC385+AC386+AC387+AC388+AC389+AC390+AC391+AC392+AC393+AC394+AC395+AC396+AC397+AC398+AC399+AC400+AC401+AC402+AC403+AC404+AC405+AC406+AC407+AC408+AC409+AC410+AC411+AC412+AC413+AC414+AC415+AC416+AC417+AC418+AC419+AC420+AC421+AC422+AC423+AC424+AC425+AC426+AC427+AC428+AC429+AC430+AC431+AC432+AC433+AC434+AC435+AC436+AC437+AC438+AC439+AC440+AC441+AC442+AC443+AC444+AC445+AC446+AC447+AC448+AC449+AC450+AC451+AC452+AC453+AC454+AC455+AC456+AC457+AC458+AC459+AC460+AC461+AC462+AC463+AC464+AC465+AC466+AC467+AC468+AC469+AC470+AC471+AC472+AC473+AC474+AC475+AC476+AC477+AC478+AC479+AC480+AC481+AC482+AC483+AC484+AC485+AC486+AC487+AC488+AC489+AC490+AC491+AC492+AC493+AC494+AC495+AC496+AC497+AC498+AC499+AC500+AC501+AC502+AC503+AC504+AC505+AC506+AC507+AC508+AC509+AC510+AC511+AC512+AC513+AC514+AC515+AC516+AC517+AC518+AC519+AC520+AC521+AC522+AC523+AC524+AC525+AC526+AC527+AC528+AC529+AC530+AC531+AC532+AC533+AC534+AC535+AC536+AC537+AC538+AC539+AC540+AC541+AC542+AC543+AC544+AC545+AC546+AC547+AC548+AC549+AC550+AC551+AC552+AC553+AC554+AC555+AC556+AC557+AC558+AC559+AC560+AC561+AC562+AC563 -> 0 | AK9: =AD9+AD10+AD11+AD12+AD13+AD14+AD15+AD16+AD17+AD18+AD19+AD20+AD21+AD22+AD23+AD24+AD25+AD26+AD27+AD28+AD29+AD30+AD31+AD32+AD33+AD34+AD35+AD36+AD37+AD38+AD39+AD40+AD41+AD42+AD43+AD44+AD45+AD47+AD48+AD49+AD50+AD51+AD52+AD53+AD54+AD55+AD56+AD57+AD58+AD59+AD60+AD61+AD62+AD63+AD64+AD65+AD66+AD67+AD68+AD69+AD70+AD71+AD72+AD73+AD74+AD75+AD76+AD77+AD78+AD79+AD80+AD81+AD82+AD83+AD84+AD85+AD86+AD87+AD88+AD89+AD90+AD91+AD92+AD93+AD94+AD95+AD96+AD97+AD98+AD99+AD100+AD101+AD102+AD103+AD104+AD105+AD106+AD107+AD108+AD109+AD110+AD111+AD112+AD113+AD114+AD115+AD116+AD117+AD118+AD119+AD120+AD121+AD122+AD123+AD124+AD125+AD126+AD127+AD128+AD129+AD130+AD131+AD132+AD133+AD134+AD135+AD136+AD137+AD138+AD139+AD140+AD141+AD142+AD143+AD144+AD145+AD146+AD147+AD148+AD149+AD150+AD151+AD152+AD153+AD154+AD155+AD156+AD157+AD158+AD159+AD160+AD161+AD162+AD163+AD164+AD165+AD166+AD167+AD168+AD169+AD170+AD171+AD172+AD173+AD174+AD175+AD176+AD177+AD178+AD179+AD180+AD181+AD182+AD183+AD184+AD185+AD186+AD187+AD188+AD189+AD190+AD191+AD192+AD193+AD194+AD195+AD196+AD197+AD198+AD199+AD200+AD201+AD202+AD203+AD204+AD205+AD206+AD207+AD208+AD209+AD210+AD211+AD212+AD213+AD214+AD215+AD216+AD217+AD218+AD219+AD220+AD221+AD222+AD223+AD224+AD225+AD226+AD227+AD228+AD229+AD230+AD231+AD232+AD233+AD234+AD235+AD236+AD237+AD238+AD239+AD240+AD241+AD242+AD243+AD244+AD245+AD246+AD247+AD248+AD249+AD250+AD251+AD252+AD253+AD254+AD255+AD256+AD257+AD258+AD259+AD260+AD261+AD262+AD263+AD264+AD265+AD266+AD267+AD268+AD269+AD270+AD271+AD272+AD273+AD274+AD275+AD276+AD277+AD278+AD279+AD280+AD281+AD282+AD283+AD284+AD285+AD286+AD287+AD288+AD289+AD290+AD291+AD292+AD293+AD294+AD295+AD296+AD297+AD298+AD299+AD300+AD301+AD302+AD303+AD304+AD305+AD306+AD307+AD308+AD309+AD310+AD311+AD312+AD313+AD314+AD315+AD316+AD317+AD318+AD319+AD320+AD321+AD322+AD323+AD324+AD325+AD326+AD327+AD328+AD329+AD330+AD331+AD332+AD333+AD334+AD335+AD336+AD337+AD338+AD339+AD340+AD341+AD342+AD343+AD344+AD345+AD346+AD347+AD348+AD349+AD350+AD351+AD352+AD353+AD354+AD355+AD356+AD357+AD358+AD359+AD360+AD361+AD362+AD363+AD364+AD365+AD366+AD367+AD368+AD369+AD370+AD371+AD372+AD373+AD374+AD375+AD376+AD377+AD378+AD379+AD380+AD381+AD382+AD383+AD384+AD385+AD386+AD387+AD388+AD389+AD390+AD391+AD392+AD393+AD394+AD395+AD396+AD397+AD398+AD399+AD400+AD401+AD402+AD403+AD404+AD405+AD406+AD407+AD408+AD409+AD410+AD411+AD412+AD413+AD414+AD415+AD416+AD417+AD418+AD419+AD420+AD421+AD422+AD423+AD424+AD425+AD426+AD427+AD428+AD429+AD430+AD431+AD432+AD433+AD434+AD435+AD436+AD437+AD438+AD439+AD440+AD441+AD442+AD443+AD444+AD445+AD446+AD447+AD448+AD449+AD450+AD451+AD452+AD453+AD454+AD455+AD456+AD457+AD458+AD459+AD460+AD461+AD462+AD463+AD464+AD465+AD466+AD467+AD468+AD469+AD470+AD471+AD472+AD473+AD474+AD475+AD476+AD477+AD478+AD479+AD480+AD481+AD482+AD483+AD484+AD485+AD486+AD487+AD488+AD489+AD490+AD491+AD492+AD493+AD494+AD495+AD496+AD497+AD498+AD499+AD500+AD501+AD502+AD503+AD504+AD505+AD506+AD507+AD508+AD509+AD510+AD511+AD512+AD513+AD514+AD515+AD516+AD517+AD518+AD519+AD520+AD521+AD522+AD523+AD524+AD525+AD526+AD527+AD528+AD529+AD530+AD531+AD532+AD533+AD534+AD535+AD536+AD537+AD538+AD539+AD540+AD541+AD542+AD543+AD544+AD545+AD546+AD547+AD548+AD549+AD550+AD551+AD552+AD553+AD554+AD555+AD556+AD557+AD558+AD559+AD560+AD561+AD562+AD563 -> 0 | AL9: =AE9+AE10+AE11+AE12+AE13+AE14+AE15+AE16+AE17+AE18+AE19+AE20+AE21+AE22+AE23+AE24+AE25+AE26+AE27+AE28+AE29+AE30+AE31+AE32+AE33+AE34+AE35+AE36+AE37+AE38+AE39+AE40+AE41+AE42+AE43+AE44+AE45+AE46+AE47+AE48+AE49+AE50+AE51+AE52+AE53+AE54+AE55+AE56+AE57+AE58+AE59+AE60+AE61+AE62+AE63+AE64+AE65+AE66+AE67+AE68+AE69+AE70+AE71+AE72+AE73+AE74+AE75+AE76+AE77+AE78+AE79+AE80+AE81+AE82+AE83+AE84+AE85+AE86+AE87+AE88+AE89+AE90+AE91+AE92+AE93+AE94+AE95+AE96+AE97+AE98+AE99+AE100+AE101+AE102+AE103+AE104+AE105+AE106+AE107+AE108+AE109+AE110+AE111+AE112+AE113+AE114+AE115+AE116+AE117+AE118+AE119+AE120+AE121+AE122+AE123+AE124+AE125+AE126+AE127+AE128+AE129+AE130+AE131+AE132+AE133+AE134+AE135+AE136+AE137+AE138+AE139+AE140+AE141+AE142+AE143+AE144+AE145+AE146+AE147+AE148+AE149+AE150+AE151+AE152+AE153+AE154+AE155+AE156+AE157+AE158+AE159+AE160+AE161+AE162+AE163+AE164+AE165+AE166+AE167+AE168+AE169+AE170+AE171+AE172+AE173+AE174+AE175+AE176+AE177+AE178+AE179+AE180+AE181+AE182+AE183+AE184+AE185+AE186+AE187+AE188+AE189+AE190+AE191+AE192+AE193+AE194+AE195+AE196+AE197+AE198+AE199+AE200+AE201+AE202+AE203+AE204+AE205+AE206+AE207+AE208+AE209+AE210+AE211+AE212+AE213+AE214+AE215+AE216+AE217+AE218+AE219+AE220+AE221+AE222+AE223+AE224+AE225+AE226+AE227+AE228+AE229+AE230+AE231+AE232+AE233+AE234+AE235+AE236+AE237+AE238+AE239+AE240+AE241+AE242+AE243+AE244+AE245+AE246+AE247+AE248+AE249+AE250+AE251+AE252+AE253+AE254+AE255+AE256+AE257+AE258+AE259+AE260+AE261+AE262+AE263+AE264+AE265+AE266+AE267+AE268+AE269+AE270+AE271+AE272+AE273+AE274+AE275+AE276+AE277+AE278+AE279+AE280+AE281+AE282+AE283+AE284+AE285+AE286+AE287+AE288+AE289+AE290+AE291+AE292+AE293+AE294+AE295+AE296+AE297+AE298+AE299+AE300+AE301+AE302+AE303+AE304+AE305+AE306+AE307+AE308+AE309+AE310+AE311+AE312+AE313+AE314+AE315+AE316+AE317+AE318+AE319+AE320+AE321+AE322+AE323+AE324+AE325+AE326+AE327+AE328+AE329+AE330+AE331+AE332+AE333+AE334+AE335+AE336+AE337+AE338+AE339+AE340+AE341+AE342+AE343+AE344+AE345+AE346+AE347+AE348+AE349+AE350+AE351+AE352+AE353+AE354+AE355+AE356+AE357+AE358+AE359+AE360+AE361+AE362+AE363+AE364+AE365+AE366+AE367+AE368+AE369+AE370+AE371+AE372+AE373+AE374+AE375+AE376+AE377+AE378+AE379+AE380+AE381+AE382+AE383+AE384+AE385+AE386+AE387+AE388+AE389+AE390+AE391+AE392+AE393+AE394+AE395+AE396+AE397+AE398+AE399+AE400+AE401+AE402+AE403+AE404+AE405+AE406+AE407+AE408+AE409+AE410+AE411+AE412+AE413+AE414+AE415+AE416+AE417+AE418+AE419+AE420+AE421+AE422+AE423+AE424+AE425+AE426+AE427+AE428+AE429+AE430+AE431+AE432+AE433+AE434+AE435+AE436+AE437+AE438+AE439+AE440+AE441+AE442+AE443+AE444+AE445+AE446+AE447+AE448+AE449+AE450+AE451+AE452+AE453+AE454+AE455+AE456+AE457+AE458+AE459+AE460+AE461+AE462+AE463+AE464+AE465+AE466+AE467+AE468+AE469+AE470+AE471+AE472+AE473+AE474+AE475+AE476+AE477+AE478+AE479+AE480+AE481+AE482+AE483+AE484+AE485+AE486+AE487+AE488+AE489+AE490+AE491+AE492+AE493+AE494+AE495+AE496+AE497+AE498+AE499+AE500+AE501+AE502+AE503+AE504+AE505+AE506+AE507+AE508+AE509+AE510+AE511+AE512+AE513+AE514+AE515+AE516+AE517+AE518+AE519+AE520+AE521+AE522+AE523+AE524+AE525+AE526+AE527+AE528+AE529+AE530+AE531+AE532+AE533+AE534+AE535+AE536+AE537+AE538+AE539+AE540+AE541+AE542+AE543+AE544+AE545+AE546+AE547+AE548+AE549+AE550+AE551+AE552+AE553+AE554+AE555+AE556+AE557+AE558+AE559+AE560+AE561+AE562+AE563 -> 0 | AM9: =AF9+AF10+AF11+AF12+AF13+AF14+AF15+AF16+AF17+AF18+AF19+AF20+AF21+AF22+AF23+AF24+AF25+AF26+AF27+AF28+AF29+AF30+AF31+AF32+AF33+AF34+AF35+AF36+AF37+AF38+AF39+AF40+AF41+AF42+AF43+AF44+AF45+AF46+AF47+AF48+AF49+AF50+AF51+AF52+AF53+AF54+AF55+AF56+AF57+AF58+AF59+AF60+AF61+AF62+AF63+AF64+AF65+AF66+AF67+AF68+AF69+AF70+AF71+AF72+AF73+AF74+AF75+AF76+AF77+AF78+AF79+AF80+AF81+AF82+AF83+AF84+AF85+AF86+AF87+AF88+AF89+AF90+AF91+AF92+AF93+AF94+AF95+AF96+AF97+AF98+AF99+AF100+AF101+AF102+AF103+AF104+AF105+AF106+AF107+AF108+AF109+AF110+AF111+AF112+AF113+AF114+AF115+AF116+AF117+AF118+AF119+AF120+AF121+AF122+AF123+AF124+AF125+AF126+AF127+AF128+AF129+AF130+AF131+AF132+AF133+AF134+AF135+AF136+AF137+AF138+AF139+AF140+AF141+AF142+AF143+AF144+AF145+AF146+AF147+AF148+AF149+AF150+AF151+AF152+AF153+AF154+AF155+AF156+AF157+AF158+AF159+AF160+AF161+AF162+AF163+AF164+AF165+AF166+AF167+AF168+AF169+AF170+AF171+AF172+AF173+AF174+AF175+AF176+AF177+AF178+AF179+AF180+AF181+AF182+AF183+AF184+AF185+AF186+AF187+AF188+AF189+AF190+AF191+AF192+AF193+AF194+AF195+AF196+AF197+AF198+AF199+AF200+AF201+AF202+AF203+AF204+AF205+AF206+AF207+AF208+AF209+AF210+AF211+AF212+AF213+AF214+AF215+AF216+AF217+AF218+AF219+AF220+AF221+AF222+AF223+AF224+AF225+AF226+AF227+AF228+AF229+AF230+AF231+AF232+AF233+AF234+AF235+AF236+AF237+AF238+AF239+AF240+AF241+AF242+AF243+AF244+AF245+AF246+AF247+AF248+AF249+AF250+AF251+AF252+AF253+AF254+AF255+AF256+AF257+AF258+AF259+AF260+AF261+AF262+AF263+AF264+AF265+AF266+AF267+AF268+AF269+AF270+AF271+AF272+AF273+AF274+AF275+AF276+AF277+AF278+AF279+AF280+AF281+AF282+AF283+AF284+AF285+AF286+AF287+AF288+AF289+AF290+AF291+AF292+AF293+AF294+AF295+AF296+AF297+AF298+AF299+AF300+AF301+AF302+AF303+AF304+AF305+AF306+AF307+AF308+AF309+AF310+AF311+AF312+AF313+AF314+AF315+AF316+AF317+AF318+AF319+AF320+AF321+AF322+AF323+AF324+AF325+AF326+AF327+AF328+AF329+AF330+AF331+AF332+AF333+AF334+AF335+AF336+AF337+AF338+AF339+AF340+AF341+AF342+AF343+AF344+AF345+AF346+AF347+AF348+AF349+AF350+AF351+AF352+AF353+AF354+AF355+AF356+AF357+AF358+AF359+AF360+AF361+AF362+AF363+AF364+AF365+AF366+AF367+AF368+AF369+AF370+AF371+AF372+AF373+AF374+AF375+AF376+AF377+AF378+AF379+AF380+AF381+AF382+AF383+AF384+AF385+AF386+AF387+AF388+AF389+AF390+AF391+AF392+AF393+AF394+AF395+AF396+AF397+AF398+AF399+AF400+AF401+AF402+AF403+AF404+AF405+AF406+AF407+AF408+AF409+AF410+AF411+AF412+AF413+AF414+AF415+AF416+AF417+AF418+AF419+AF420+AF421+AF422+AF423+AF424+AF425+AF426+AF427+AF428+AF429+AF430+AF431+AF432+AF433+AF434+AF435+AF436+AF437+AF438+AF439+AF440+AF441+AF442+AF443+AF444+AF445+AF446+AF447+AF448+AF449+AF450+AF451+AF452+AF453+AF454+AF455+AF456+AF457+AF458+AF459+AF460+AF461+AF462+AF463+AF464+AF465+AF466+AF467+AF468+AF469+AF470+AF471+AF472+AF473+AF474+AF475+AF476+AF477+AF478+AF479+AF480+AF481+AF482+AF483+AF484+AF485+AF486+AF487+AF488+AF489+AF490+AF491+AF492+AF493+AF494+AF495+AF496+AF497+AF498+AF499+AF500+AF501+AF502+AF503+AF504+AF505+AF506+AF507+AF508+AF509+AF510+AF511+AF512+AF513+AF514+AF515+AF516+AF517+AF518+AF519+AF520+AF521+AF522+AF523+AF524+AF525+AF526+AF527+AF528+AF529+AF530+AF531+AF532+AF533+AF534+AF535+AF536+AF537+AF538+AF539+AF540+AF541+AF542+AF543+AF544+AF545+AF546+AF547+AF548+AF549+AF550+AF551+AF552+AF553+AF554+AF555+AF556+AF557+AF558+AF559+AF560+AF561+AF562+AF563 -> 0 | AN9: =AG9+AG10+AG11+AG12+AG13+AG14+AG15+AG16+AG17+AG18+AG19+AG20+AG21+AG22+AG23+AG24+AG25+AG26+AG27+AG28+AG29+AG30+AG31+AG32+AG33+AG34+AG35+AG36+AG37+AG38+AG39+AG40+AG41+AG42+AG43+AG44+AG45+AG46+AG47+AG48+AG49+AG50+AG51+AG52+AG53+AG54+AG55+AG56+AG57+AG58+AG59+AG60+AG61+AG62+AG63+AG64+AG65+AG66+AG67+AG68+AG69+AG70+AG71+AG72+AG73+AG74+AG75+AG76+AG77+AG78+AG79+AG80+AG81+AG82+AG83+AG84+AG85+AG86+AG87+AG88+AG89+AG90+AG91+AG92+AG93+AG94+AG95+AG96+AG97+AG98+AG99+AG100+AG101+AG102+AG103+AG104+AG105+AG106+AG107+AG108+AG109+AG110+AG111+AG112+AG113+AG114+AG115+AG116+AG117+AG118+AG119+AG120+AG121+AG122+AG123+AG124+AG125+AG126+AG127+AG128+AG129+AG130+AG131+AG132+AG133+AG134+AG135+AG136+AG137+AG138+AG139+AG140+AG141+AG142+AG143+AG144+AG145+AG146+AG147+AG148+AG149+AG150+AG151+AG152+AG153+AG154+AG155+AG156+AG157+AG158+AG159+AG160+AG161+AG162+AG163+AG164+AG165+AG166+AG167+AG168+AG169+AG170+AG171+AG172+AG173+AG174+AG175+AG176+AG177+AG178+AG179+AG180+AG181+AG182+AG183+AG184+AG185+AG186+AG187+AG188+AG189+AG190+AG191+AG192+AG193+AG194+AG195+AG196+AG197+AG198+AG199+AG200+AG201+AG202+AG203+AG204+AG205+AG206+AG207+AG208+AG209+AG210+AG211+AG212+AG213+AG214+AG215+AG216+AG217+AG218+AG219+AG220+AG221+AG222+AG223+AG224+AG225+AG226+AG227+AG228+AG229+AG230+AG231+AG232+AG233+AG234+AG235+AG236+AG237+AG238+AG239+AG240+AG241+AG242+AG243+AG244+AG245+AG246+AG247+AG248+AG249+AG250+AG251+AG252+AG253+AG254+AG255+AG256+AG257+AG258+AG259+AG260+AG261+AG262+AG263+AG264+AG265+AG266+AG267+AG268+AG269+AG270+AG271+AG272+AG273+AG274+AG275+AG276+AG277+AG278+AG279+AG280+AG281+AG282+AG283+AG284+AG285+AG286+AG287+AG288+AG289+AG290+AG291+AG292+AG293+AG294+AG295+AG296+AG297+AG298+AG299+AG300+AG301+AG302+AG303+AG304+AG305+AG306+AG307+AG308+AG309+AG310+AG311+AG312+AG313+AG314+AG315+AG316+AG317+AG318+AG319+AG320+AG321+AG322+AG323+AG324+AG325+AG326+AG327+AG328+AG329+AG330+AG331+AG332+AG333+AG334+AG335+AG336+AG337+AG338+AG339+AG340+AG341+AG342+AG343+AG344+AG345+AG346+AG347+AG348+AG349+AG350+AG351+AG352+AG353+AG354+AG355+AG356+AG357+AG358+AG359+AG360+AG361+AG362+AG363+AG364+AG365+AG366+AG367+AG368+AG369+AG370+AG371+AG372+AG373+AG374+AG375+AG376+AG377+AG378+AG379+AG380+AG381+AG382+AG383+AG384+AG385+AG386+AG387+AG388+AG389+AG390+AG391+AG392+AG393+AG394+AG395+AG396+AG397+AG398+AG399+AG400+AG401+AG402+AG403+AG404+AG405+AG406+AG407+AG408+AG409+AG410+AG411+AG412+AG413+AG414+AG415+AG416+AG417+AG418+AG419+AG420+AG421+AG422+AG423+AG424+AG425+AG426+AG427+AG428+AG429+AG430+AG431+AG432+AG433+AG434+AG435+AG436+AG437+AG438+AG439+AG440+AG441+AG442+AG443+AG444+AG445+AG446+AG447+AG448+AG449+AG450+AG451+AG452+AG453+AG454+AG455+AG456+AG457+AG458+AG459+AG460+AG461+AG462+AG463+AG464+AG465+AG466+AG467+AG468+AG469+AG470+AG471+AG472+AG473+AG474+AG475+AG476+AG477+AG478+AG479+AG480+AG481+AG482+AG483+AG484+AG485+AG486+AG487+AG488+AG489+AG490+AG491+AG492+AG493+AG494+AG495+AG496+AG497+AG498+AG499+AG500+AG501+AG502+AG503+AG504+AG505+AG506+AG507+AG508+AG509+AG510+AG511+AG512+AG513+AG514+AG515+AG516+AG517+AG518+AG519+AG520+AG521+AG522+AG523+AG524+AG525+AG526+AG527+AG528+AG529+AG530+AG531+AG532+AG533+AG534+AG535+AG536+AG537+AG538+AG539+AG540+AG541+AG542+AG543+AG544+AG545+AG546+AG547+AG548+AG549+AG550+AG551+AG552+AG553+AG554+AG555+AG556+AG557+AG558+AG559+AG560+AG561+AG562+AG563 -> 0 | AO9: 1 | AP9: =U9*B9 -> 0 | AQ9: =U9*C9 -> 0 | AR9: =AQ9-AP9 -> 0 | AS9: =X9*B9 -> 3900
A10: 2 | B10: 1900 | C10: 3000 | D10: 1100 | E10: Lonas Medianas | F10: 3 | U10: =H10+J10+L10+N10+P10+R10+T10 -> 0 | X10: =F10+G10+I10+K10+M10+O10+Q10+S10-H10-J10-L10-N10-P10-R10-T10-V10-W10 -> 3 | Y10: =G10+I10+K10+M10+O10+Q10+S10 -> 0 | Z10: =Y10*B10 -> 0 | AA10: =H10*C10 -> 0 | AB10: =J10*C10 -> 0 | AC10: =L10*C10 -> 0 | AD10: =N10*C10 -> 0 | AE10: =P10*C10 -> 0 | AF10: =R10*C10 -> 0 | AG10: =T10*C10 -> 0 | AO10: 2 | AP10: =U10*B10 -> 0 | AQ10: =U10*C10 -> 0 | AR10: =AQ10-AP10 -> 0 | AS10: =X10*B10 -> 5700
A11: 3 | B11: 2100 | C11: 3500 | D11: 1400 | E11: Lonas Grandes | F11: 2 | U11: =H11+J11+L11+N11+P11+R11+T11 -> 0 | X11: =F11+G11+I11+K11+M11+O11+Q11+S11-H11-J11-L11-N11-P11-R11-T11-V11-W11 -> 2 | Y11: =G11+I11+K11+M11+O11+Q11+S11 -> 0 | Z11: =Y11*B11 -> 0 | AA11: =H11*C11 -> 0 | AB11: =J11*C11 -> 0 | AC11: =L11*C11 -> 0 | AD11: =N11*C11 -> 0 | AE11: =P11*C11 -> 0 | AF11: =R11*C11 -> 0 | AG11: =T11*C11 -> 0 | AO11: 3 | AP11: =U11*B11 -> 0 | AQ11: =U11*C11 -> 0 | AR11: =AQ11-AP11 -> 0 | AS11: =X11*B11 -> 4200
A12: 4 | U12: =H12+J12+L12+N12+P12+R12+T12 -> 0 | X12: =F12+G12+I12+K12+M12+O12+Q12+S12-H12-J12-L12-N12-P12-R12-T12-V12-W12 -> 0 | Y12: =G12+I12+K12+M12+O12+Q12+S12 -> 0 | Z12: =Y12*B12 -> 0 | AA12: =H12*C12 -> 0 | AB12: =J12*C12 -> 0 | AC12: =L12*C12 -> 0 | AD12: =N12*C12 -> 0 | AE12: =P12*C12 -> 0 | AF12: =R12*C12 -> 0 | AG12: =T12*C12 -> 0 | AH12: Total de la semana | AI12: =AH9+AI9+AJ9+AK9+AL9+AM9+AN9 -> 0 | AO12: 4 | AP12: =U12*B12 -> 0 | AQ12: =U12*C12 -> 0 | AR12: =AQ12-AP12 -> 0 | AS12: =X12*B12 -> 0
A13: 5 | U13: =H13+J13+L13+N13+P13+R13+T13 -> 0 | X13: =F13+G13+I13+K13+M13+O13+Q13+S13-H13-J13-L13-N13-P13-R13-T13-V13-W13 -> 0 | Y13: =G13+I13+K13+M13+O13+Q13+S13 -> 0 | Z13: =Y13*B13 -> 0 | AA13: =H13*C13 -> 0 | AB13: =J13*C13 -> 0 | AC13: =L13*C13 -> 0 | AD13: =N13*C13 -> 0 | AE13: =P13*C13 -> 0 | AF13: =R13*C13 -> 0 | AG13: =T13*C13 -> 0 | AO13: 5 | AP13: =U13*B13 -> 0 | AQ13: =U13*C13 -> 0 | AR13: =AQ13-AP13 -> 0 | AS13: =X13*B13 -> 0
A14: 6 | U14: =H14+J14+L14+N14+P14+R14+T14 -> 0 | X14: =F14+G14+I14+K14+M14+O14+Q14+S14-H14-J14-L14-N14-P14-R14-T14-V14-W14 -> 0 | Y14: =G14+I14+K14+M14+O14+Q14+S14 -> 0 | Z14: =Y14*B14 -> 0 | AA14: =H14*C14 -> 0 | AB14: =J14*C14 -> 0 | AC14: =L14*C14 -> 0 | AD14: =N14*C14 -> 0 | AE14: =P14*C14 -> 0 | AF14: =R14*C14 -> 0 | AG14: =T14*C14 -> 0 | AO14: 6 | AP14: =U14*B14 -> 0 | AQ14: =U14*C14 -> 0 | AR14: =AQ14-AP14 -> 0 | AS14: =X14*B14 -> 0
A15: 7 | U15: =H15+J15+L15+N15+P15+R15+T15 -> 0 | X15: =F15+G15+I15+K15+M15+O15+Q15+S15-H15-J15-L15-N15-P15-R15-T15-V15-W15 -> 0 | Y15: =G15+I15+K15+M15+O15+Q15+S15 -> 0 | Z15: =Y15*B15 -> 0 | AA15: =H15*C15 -> 0 | AB15: =J15*C15 -> 0 | AC15: =L15*C15 -> 0 | AD15: =N15*C15 -> 0 | AE15: =P15*C15 -> 0 | AF15: =R15*C15 -> 0 | AG15: =T15*C15 -> 0 | AO15: 7 | AP15: =U15*B15 -> 0 | AQ15: =U15*C15 -> 0 | AR15: =AQ15-AP15 -> 0 | AS15: =X15*B15 -> 0
A16: 8 | B16: 200 | C16: 300 | D16: =C16-B16 -> 100 | E16: Plato Chico | F16: 6 | U16: =H16+J16+L16+N16+P16+R16+T16 -> 0 | X16: =F16+G16+I16+K16+M16+O16+Q16+S16-H16-J16-L16-N16-P16-R16-T16-V16-W16 -> 6 | Y16: =G16+I16+K16+M16+O16+Q16+S16 -> 0 | Z16: =Y16*B16 -> 0 | AA16: =H16*C16 -> 0 | AB16: =J16*C16 -> 0 | AC16: =L16*C16 -> 0 | AD16: =N16*C16 -> 0 | AE16: =P16*C16 -> 0 | AF16: =R16*C16 -> 0 | AG16: =T16*C16 -> 0 | AO16: 9 | AP16: =U16*B16 -> 0 | AQ16: =U16*C16 -> 0 | AR16: =AQ16-AP16 -> 0 | AS16: =X16*B16 -> 1200
A17: 9 | B17: 300 | C17: 400 | D17: =C17-B17 -> 100 | E17: Plato Mediano | F17: 0 | U17: =H17+J17+L17+N17+P17+R17+T17 -> 0 | X17: =F17+G17+I17+K17+M17+O17+Q17+S17-H17-J17-L17-N17-P17-R17-T17-V17-W17 -> 0 | Y17: =G17+I17+K17+M17+O17+Q17+S17 -> 0 | Z17: =Y17*B17 -> 0 | AA17: =H17*C17 -> 0 | AB17: =J17*C17 -> 0 | AC17: =L17*C17 -> 0 | AD17: =N17*C17 -> 0 | AE17: =P17*C17 -> 0 | AF17: =R17*C17 -> 0 | AG17: =T17*C17 -> 0 | AO17: 10 | AP17: =U17*B17 -> 0 | AQ17: =U17*C17 -> 0 | AR17: =AQ17-AP17 -> 0 | AS17: =X17*B17 -> 0
A18: 10 | B18: 400 | C18: 600 | D18: =C18-B18 -> 200 | E18: Platos Grandes | F18: 0 | U18: =H18+J18+L18+N18+P18+R18+T18 -> 0 | X18: =F18+G18+I18+K18+M18+O18+Q18+S18-H18-J18-L18-N18-P18-R18-T18-V18-W18 -> 0 | Y18: =G18+I18+K18+M18+O18+Q18+S18 -> 0 | Z18: =Y18*B18 -> 0 | AA18: =H18*C18 -> 0 | AB18: =J18*C18 -> 0 | AC18: =L18*C18 -> 0 | AD18: =N18*C18 -> 0 | AE18: =P18*C18 -> 0 | AF18: =R18*C18 -> 0 | AG18: =T18*C18 -> 0 | AO18: 11 | AP18: =U18*B18 -> 0 | AQ18: =U18*C18 -> 0 | AR18: =AQ18-AP18 -> 0 | AS18: =X18*B18 -> 0
A19: 11 | U19: =H19+J19+L19+N19+P19+R19+T19 -> 0 | X19: =F19+G19+I19+K19+M19+O19+Q19+S19-H19-J19-L19-N19-P19-R19-T19-V19-W19 -> 0 | Y19: =G19+I19+K19+M19+O19+Q19+S19 -> 0 | Z19: =Y19*B19 -> 0 | AA19: =H19*C19 -> 0 | AB19: =J19*C19 -> 0 | AC19: =L19*C19 -> 0 | AD19: =N19*C19 -> 0 | AE19: =P19*C19 -> 0 | AF19: =R19*C19 -> 0 | AG19: =T19*C19 -> 0 | AO19: 12 | AP19: =U19*B19 -> 0 | AQ19: =U19*C19 -> 0 | AR19: =AQ19-AP19 -> 0 | AS19: =X19*B19 -> 0
A20: 12 | U20: =H20+J20+L20+N20+P20+R20+T20 -> 0 | X20: =F20+G20+I20+K20+M20+O20+Q20+S20-H20-J20-L20-N20-P20-R20-T20-V20-W20 -> 0 | Y20: =G20+I20+K20+M20+O20+Q20+S20 -> 0 | Z20: =Y20*B20 -> 0 | AA20: =H20*C20 -> 0 | AB20: =J20*C20 -> 0 | AC20: =L20*C20 -> 0 | AD20: =N20*C20 -> 0 | AE20: =P20*C20 -> 0 | AF20: =R20*C20 -> 0 | AG20: =T20*C20 -> 0 | AO20: 13 | AP20: =U20*B20 -> 0 | AQ20: =U20*C20 -> 0 | AR20: =AQ20-AP20 -> 0 | AS20: =X20*B20 -> 0
A21: 13 | U21: =H21+J21+L21+N21+P21+R21+T21 -> 0 | X21: =F21+G21+I21+K21+M21+O21+Q21+S21-H21-J21-L21-N21-P21-R21-T21-V21-W21 -> 0 | Y21: =G21+I21+K21+M21+O21+Q21+S21 -> 0 | Z21: =Y21*B21 -> 0 | AA21: =H21*C21 -> 0 | AB21: =J21*C21 -> 0 | AC21: =L21*C21 -> 0 | AD21: =N21*C21 -> 0 | AE21: =P21*C21 -> 0 | AF21: =R21*C21 -> 0 | AG21: =T21*C21 -> 0 | AO21: 14 | AP21: =U21*B21 -> 0 | AQ21: =U21*C21 -> 0 | AR21: =AQ21-AP21 -> 0 | AS21: =X21*B21 -> 0
A22: 14 | U22: =H22+J22+L22+N22+P22+R22+T22 -> 0 | X22: =F22+G22+I22+K22+M22+O22+Q22+S22-H22-J22-L22-N22-P22-R22-T22-V22-W22 -> 0 | Y22: =G22+I22+K22+M22+O22+Q22+S22 -> 0 | Z22: =Y22*B22 -> 0 | AA22: =H22*C22 -> 0 | AB22: =J22*C22 -> 0 | AC22: =L22*C22 -> 0 | AD22: =N22*C22 -> 0 | AE22: =P22*C22 -> 0 | AF22: =R22*C22 -> 0 | AG22: =T22*C22 -> 0 | AO22: 15 | AP22: =U22*B22 -> 0 | AQ22: =U22*C22 -> 0 | AR22: =AQ22-AP22 -> 0 | AS22: =X22*B22 -> 0
A23: 15 | U23: =H23+J23+L23+N23+P23+R23+T23 -> 0 | X23: =F23+G23+I23+K23+M23+O23+Q23+S23-H23-J23-L23-N23-P23-R23-T23-V23-W23 -> 0 | Y23: =G23+I23+K23+M23+O23+Q23+S23 -> 0 | Z23: =Y23*B23 -> 0 | AA23: =H23*C23 -> 0 | AB23: =J23*C23 -> 0 | AC23: =L23*C23 -> 0 | AD23: =N23*C23 -> 0 | AE23: =P23*C23 -> 0 | AF23: =R23*C23 -> 0 | AG23: =T23*C23 -> 0 | AO23: 16 | AP23: =U23*B23 -> 0 | AQ23: =U23*C23 -> 0 | AR23: =AQ23-AP23 -> 0 | AS23: =X23*B23 -> 0
A24: 16 | U24: =H24+J24+L24+N24+P24+R24+T24 -> 0 | X24: =F24+G24+I24+K24+M24+O24+Q24+S24-H24-J24-L24-N24-P24-R24-T24-V24-W24 -> 0 | Y24: =G24+I24+K24+M24+O24+Q24+S24 -> 0 | Z24: =Y24*B24 -> 0 | AA24: =H24*C24 -> 0 | AB24: =J24*C24 -> 0 | AC24: =L24*C24 -> 0 | AD24: =N24*C24 -> 0 | AE24: =P24*C24 -> 0 | AF24: =R24*C24 -> 0 | AG24: =T24*C24 -> 0 | AO24: 17 | AP24: =U24*B24 -> 0 | AQ24: =U24*C24 -> 0 | AR24: =AQ24-AP24 -> 0 | AS24: =X24*B24 -> 0
A25: 17 | U25: =H25+J25+L25+N25+P25+R25+T25 -> 0 | X25: =F25+G25+I25+K25+M25+O25+Q25+S25-H25-J25-L25-N25-P25-R25-T25-V25-W25 -> 0 | Y25: =G25+I25+K25+M25+O25+Q25+S25 -> 0 | Z25: =Y25*B25 -> 0 | AA25: =H25*C25 -> 0 | AB25: =J25*C25 -> 0 | AC25: =L25*C25 -> 0 | AD25: =N25*C25 -> 0 | AE25: =P25*C25 -> 0 | AF25: =R25*C25 -> 0 | AG25: =T25*C25 -> 0 | AO25: 18 | AP25: =U25*B25 -> 0 | AQ25: =U25*C25 -> 0 | AR25: =AQ25-AP25 -> 0 | AS25: =X25*B25 -> 0
A26: 18 | U26: =H26+J26+L26+N26+P26+R26+T26 -> 0 | X26: =F26+G26+I26+K26+M26+O26+Q26+S26-H26-J26-L26-N26-P26-R26-T26-V26-W26 -> 0 | Y26: =G26+I26+K26+M26+O26+Q26+S26 -> 0 | Z26: =Y26*B26 -> 0 | AA26: =H26*C26 -> 0 | AB26: =J26*C26 -> 0 | AC26: =L26*C26 -> 0 | AD26: =N26*C26 -> 0 | AE26: =P26*C26 -> 0 | AF26: =R26*C26 -> 0 | AG26: =T26*C26 -> 0 | AO26: 19 | AP26: =U26*B26 -> 0 | AQ26: =U26*C26 -> 0 | AR26: =AQ26-AP26 -> 0 | AS26: =X26*B26 -> 0
A27: 19 | U27: =H27+J27+L27+N27+P27+R27+T27 -> 0 | X27: =F27+G27+I27+K27+M27+O27+Q27+S27-H27-J27-L27-N27-P27-R27-T27-V27-W27 -> 0 | Y27: =G27+I27+K27+M27+O27+Q27+S27 -> 0 | Z27: =Y27*B27 -> 0 | AA27: =H27*C27 -> 0 | AB27: =J27*C27 -> 0 | AC27: =L27*C27 -> 0 | AD27: =N27*C27 -> 0 | AE27: =P27*C27 -> 0 | AF27: =R27*C27 -> 0 | AG27: =T27*C27 -> 0 | AO27: 20 | AP27: =U27*B27 -> 0 | AQ27: =U27*C27 -> 0 | AR27: =AQ27-AP27 -> 0 | AS27: =X27*B27 -> 0
A28: 20 | U28: =H28+J28+L28+N28+P28+R28+T28 -> 0 | X28: =F28+G28+I28+K28+M28+O28+Q28+S28-H28-J28-L28-N28-P28-R28-T28-V28-W28 -> 0 | Y28: =G28+I28+K28+M28+O28+Q28+S28 -> 0 | Z28: =Y28*B28 -> 0 | AA28: =H28*C28 -> 0 | AB28: =J28*C28 -> 0 | AC28: =L28*C28 -> 0 | AD28: =N28*C28 -> 0 | AE28: =P28*C28 -> 0 | AF28: =R28*C28 -> 0 | AG28: =T28*C28 -> 0 | AO28: 21 | AP28: =U28*B28 -> 0 | AQ28: =U28*C28 -> 0 | AR28: =AQ28-AP28 -> 0 | AS28: =X28*B28 -> 0
A29: 21 | U29: =H29+J29+L29+N29+P29+R29+T29 -> 0 | X29: =F29+G29+I29+K29+M29+O29+Q29+S29-H29-J29-L29-N29-P29-R29-T29-V29-W29 -> 0 | Y29: =G29+I29+K29+M29+O29+Q29+S29 -> 0 | Z29: =Y29*B29 -> 0 | AA29: =H29*C29 -> 0 | AB29: =J29*C29 -> 0 | AC29: =L29*C29 -> 0 | AD29: =N29*C29 -> 0 | AE29: =P29*C29 -> 0 | AF29: =R29*C29 -> 0 | AG29: =T29*C29 -> 0 | AO29: 22 | AP29: =U29*B29 -> 0 | AQ29: =U29*C29 -> 0 | AR29: =AQ29-AP29 -> 0 | AS29: =X29*B29 -> 0
A30: 22 | U30: =H30+J30+L30+N30+P30+R30+T30 -> 0 | X30: =F30+G30+I30+K30+M30+O30+Q30+S30-H30-J30-L30-N30-P30-R30-T30-V30-W30 -> 0 | Y30: =G30+I30+K30+M30+O30+Q30+S30 -> 0 | Z30: =Y30*B30 -> 0 | AA30: =H30*C30 -> 0 | AB30: =J30*C30 -> 0 | AC30: =L30*C30 -> 0 | AD30: =N30*C30 -> 0 | AE30: =P30*C30 -> 0 | AF30: =R30*C30 -> 0 | AG30: =T30*C30 -> 0 | AO30: 23 | AP30: =U30*B30 -> 0 | AQ30: =U30*C30 -> 0 | AR30: =AQ30-AP30 -> 0 | AS30: =X30*B30 -> 0
... A45: 37 | U45: =H45+J45+L45+N45+P45+R45+T45 -> 0 | X45: =F45+G45+I45+K45+M45+O45+Q45+S45-H45-J45-L45-N45-P45-R45-T45-V45-W45 -> 0 | Y45: =G45+I45+K45+M45+O45+Q45+S45 -> 0 | Z45: =Y45*B45 -> 0 | AA45: =H45*C45 -> 0 | AB45: =J45*C45 -> 0 | AC45: =L45*C45 -> 0 | AD45: =N45*C45 -> 0 | AE45: =P45*C45 -> 0 | AF45: =R45*C45 -> 0 | AG45: =T45*C45 -> 0 | AO45: 38 | AP45: =U45*B45 -> 0 | AQ45: =U45*C45 -> 0 | AR45: =AQ45-AP45 -> 0 | AS45: =X45*B45 -> 0
A46: 38 | U46: =H46+J46+L46+N46+P46+R46+T46 -> 0 | X46: =F46+G46+I46+K46+M46+O46+Q46+S46-H46-J46-L46-N46-P46-R46-T46-V46-W46 -> 0 | Y46: =G46+I46+K46+M46+O46+Q46+S46 -> 0 | Z46: =Y46*B46 -> 0 | AA46: =H46*C46 -> 0 | AB46: =J46*C46 -> 0 | AC46: =L46*C46 -> 0 | AD46: =N46*C46 -> 0 | AE46: =P46*C46 -> 0 | AF46: =R46*C46 -> 0 | AG46: =T46*C46 -> 0 | AO46: 39 | AP46: =U46*B46 -> 0 | AQ46: =U46*C46 -> 0 | AS46: =X46*B46 -> 0
A47: 39 | U47: =H47+J47+L47+N47+P47+R47+T47 -> 0 | X47: =F47+G47+I47+K47+M47+O47+Q47+S47-H47-J47-L47-N47-P47-R47-T47-V47-W47 -> 0 | Y47: =G47+I47+K47+M47+O47+Q47+S47 -> 0 | Z47: =Y47*B47 -> 0 | AA47: =H47*C47 -> 0 | AB47: =J47*C47 -> 0 | AC47: =L47*C47 -> 0 | AD47: =N47*C47 -> 0 | AE47: =P47*C47 -> 0 | AF47: =R47*C47 -> 0 | AG47: =T47*C47 -> 0 | AO47: 40 | AP47: =U47*B47 -> 0 | AQ47: =U47*C47 -> 0 | AR47: =AQ47-AP47 -> 0 | AS47: =X47*B47 -> 0
A48: 40 | U48: =H48+J48+L48+N48+P48+R48+T48 -> 0 | X48: =F48+G48+I48+K48+M48+O48+Q48+S48-H48-J48-L48-N48-P48-R48-T48-V48-W48 -> 0 | Y48: =G48+I48+K48+M48+O48+Q48+S48 -> 0 | Z48: =Y48*B48 -> 0 | AA48: =H48*C48 -> 0 | AB48: =J48*C48 -> 0 | AC48: =L48*C48 -> 0 | AD48: =N48*C48 -> 0 | AE48: =P48*C48 -> 0 | AF48: =R48*C48 -> 0 | AG48: =T48*C48 -> 0 | AO48: 41 | AP48: =U48*B48 -> 0 | AQ48: =U48*C48 -> 0 | AR48: =AQ48-AP48 -> 0 | AS48: =X48*B48 -> 0
A49: 41 | U49: =H49+J49+L49+N49+P49+R49+T49 -> 0 | X49: =F49+G49+I49+K49+M49+O49+Q49+S49-H49-J49-L49-N49-P49-R49-T49-V49-W49 -> 0 | Y49: =G49+I49+K49+M49+O49+Q49+S49 -> 0 | Z49: =Y49*B49 -> 0 | AA49: =H49*C49 -> 0 | AB49: =J49*C49 -> 0 | AC49: =L49*C49 -> 0 | AD49: =N49*C49 -> 0 | AE49: =P49*C49 -> 0 | AF49: =R49*C49 -> 0 | AG49: =T49*C49 -> 0 | AO49: 42 | AP49: =U49*B49 -> 0 | AQ49: =U49*C49 -> 0 | AR49: =AQ49-AP49 -> 0 | AS49: =X49*B49 -> 0
A50: 42 | U50: =H50+J50+L50+N50+P50+R50+T50 -> 0 | X50: =F50+G50+I50+K50+M50+O50+Q50+S50-H50-J50-L50-N50-P50-R50-T50-V50-W50 -> 0 | Y50: =G50+I50+K50+M50+O50+Q50+S50 -> 0 | Z50: =Y50*B50 -> 0 | AA50: =H50*C50 -> 0 | AB50: =J50*C50 -> 0 | AC50: =L50*C50 -> 0 | AD50: =N50*C50 -> 0 | AE50: =P50*C50 -> 0 | AF50: =R50*C50 -> 0 | AG50: =T50*C50 -> 0 | AO50: 43 | AP50: =U50*B50 -> 0 | AQ50: =U50*C50 -> 0 | AR50: =AQ50-AP50 -> 0 | AS50: =X50*B50 -> 0
A51: 43 | U51: =H51+J51+L51+N51+P51+R51+T51 -> 0 | X51: =F51+G51+I51+K51+M51+O51+Q51+S51-H51-J51-L51-N51-P51-R51-T51-V51-W51 -> 0 | Y51: =G51+I51+K51+M51+O51+Q51+S51 -> 0 | Z51: =Y51*B51 -> 0 | AA51: =H51*C51 -> 0 | AB51: =J51*C51 -> 0 | AC51: =L51*C51 -> 0 | AD51: =N51*C51 -> 0 | AE51: =P51*C51 -> 0 | AF51: =R51*C51 -> 0 | AG51: =T51*C51 -> 0 | AO51: 44 | AP51: =U51*B51 -> 0 | AQ51: =U51*C51 -> 0 | AR51: =AQ51-AP51 -> 0 | AS51: =X51*B51 -> 0
A52: 44 | U52: =H52+J52+L52+N52+P52+R52+T52 -> 0 | X52: =F52+G52+I52+K52+M52+O52+Q52+S52-H52-J52-L52-N52-P52-R52-T52-V52-W52 -> 0 | Y52: =G52+I52+K52+M52+O52+Q52+S52 -> 0 | Z52: =Y52*B52 -> 0 | AA52: =H52*C52 -> 0 | AB52: =J52*C52 -> 0 | AC52: =L52*C52 -> 0 | AD52: =N52*C52 -> 0 | AE52: =P52*C52 -> 0 | AF52: =R52*C52 -> 0 | AG52: =T52*C52 -> 0 | AO52: 45 | AP52: =U52*B52 -> 0 | AQ52: =U52*C52 -> 0 | AR52: =AQ52-AP52 -> 0 | AS52: =X52*B52 -> 0
A53: 45 | U53: =H53+J53+L53+N53+P53+R53+T53 -> 0 | X53: =F53+G53+I53+K53+M53+O53+Q53+S53-H53-J53-L53-N53-P53-R53-T53-V53-W53 -> 0 | Y53: =G53+I53+K53+M53+O53+Q53+S53 -> 0 | Z53: =Y53*B53 -> 0 | AA53: =H53*C53 -> 0 | AB53: =J53*C53 -> 0 | AC53: =L53*C53 -> 0 | AD53: =N53*C53 -> 0 | AE53: =P53*C53 -> 0 | AF53: =R53*C53 -> 0 | AG53: =T53*C53 -> 0 | AO53: 46 | AP53: =U53*B53 -> 0 | AQ53: =U53*C53 -> 0 | AR53: =AQ53-AP53 -> 0 | AS53: =X53*B53 -> 0
A54: 46 | U54: =H54+J54+L54+N54+P54+R54+T54 -> 0 | X54: =F54+G54+I54+K54+M54+O54+Q54+S54-H54-J54-L54-N54-P54-R54-T54-V54-W54 -> 0 | Y54: =G54+I54+K54+M54+O54+Q54+S54 -> 0 | Z54: =Y54*B54 -> 0 | AA54: =H54*C54 -> 0 | AB54: =J54*C54 -> 0 | AC54: =L54*C54 -> 0 | AD54: =N54*C54 -> 0 | AE54: =P54*C54 -> 0 | AF54: =R54*C54 -> 0 | AG54: =T54*C54 -> 0 | AO54: 47 | AP54: =U54*B54 -> 0 | AQ54: =U54*C54 -> 0 | AR54: =AQ54-AP54 -> 0 | AS54: =X54*B54 -> 0
A55: 47 | U55: =H55+J55+L55+N55+P55+R55+T55 -> 0 | X55: =F55+G55+I55+K55+M55+O55+Q55+S55-H55-J55-L55-N55-P55-R55-T55-V55-W55 -> 0 | Y55: =G55+I55+K55+M55+O55+Q55+S55 -> 0 | Z55: =Y55*B55 -> 0 | AA55: =H55*C55 -> 0 | AB55: =J55*C55 -> 0 | AC55: =L55*C55 -> 0 | AD55: =N55*C55 -> 0 | AE55: =P55*C55 -> 0 | AF55: =R55*C55 -> 0 | AG55: =T55*C55 -> 0 | AO55: 48 | AP55: =U55*B55 -> 0 | AQ55: =U55*C55 -> 0 | AR55: =AQ55-AP55 -> 0 | AS55: =X55*B55 -> 0
A56: 48 | U56: =H56+J56+L56+N56+P56+R56+T56 -> 0 | X56: =F56+G56+I56+K56+M56+O56+Q56+S56-H56-J56-L56-N56-P56-R56-T56-V56-W56 -> 0 | Y56: =G56+I56+K56+M56+O56+Q56+S56 -> 0 | Z56: =Y56*B56 -> 0 | AA56: =H56*C56 -> 0 | AB56: =J56*C56 -> 0 | AC56: =L56*C56 -> 0 | AD56: =N56*C56 -> 0 | AE56: =P56*C56 -> 0 | AF56: =R56*C56 -> 0 | AG56: =T56*C56 -> 0 | AO56: 49 | AP56: =U56*B56 -> 0 | AQ56: =U56*C56 -> 0 | AR56: =AQ56-AP56 -> 0 | AS56: =X56*B56 -> 0
...

Sheet Ceramica y Reloj
A1: Basar Ojos Color Sol | Y1: Entradas totales de la semana | Z1: Importe de las Entradas Semanal | AO1: Importe en $
AA2: Basar Ojos Color Sol | AH2: Basar Ojos Color Sol
A5: INVENTARIO | F5: ='Lienzos y espejos'!F5:F7 -> 46152 | G5: ='Lienzos y espejos'!G5:T5 -> Semana del 11 al 16 de Mayo | U5: Venta Total | V5: Deuda | W5: Baja sem. | X5: ='Lienzos y espejos'!X5:X7 -> F. 16/5 /26 | AO5: No | AP5: Total al costo | AQ5: Total a la Venta | AR5: Utilidad Total | AS5: $ en Mercancia
G6: ='Lienzos y espejos'!G6:H6 -> D-10 | I6: ='Lienzos y espejos'!I6:J6 -> L-11 | K6: ='Lienzos y espejos'!K6:L6 -> M-12 | M6: ='Lienzos y espejos'!M6:N6 -> Mi-13 | O6: ='Lienzos y espejos'!O6:P6 -> J-14 | Q6: ='Lienzos y espejos'!Q6:R6 -> V-15 | S6: ='Lienzos y espejos'!S6:T6 -> S-16 | AA6: =G5 -> Semana del 11 al 16 de Mayo | AH6: =AA6 -> Semana del 11 al 16 de Mayo
A7: No | B7: Costo | C7: Venta | D7: Gan. | E7: Producto | G7: Entra. | H7: Venta | I7: Entra. | J7: Venta | K7: Entra. | L7: Venta | M7: Entra. | N7: Venta | O7: Entra. | P7: Venta | Q7: Entra. | R7: Venta | S7: Entra. | T7: Venta | AA7: Domingo | AB7: Lunes | AC7: martes | AD7: Miercoles | AE7: Jueves | AF7: Viernes | AG7: Sabado | AH7: Cuadre en efectivo de la Semana
E8: Relojes | Z8: =Z9+Z10+Z11+Z12+Z13+Z14+Z15+Z16+Z17+Z18+Z19+Z20+Z21+Z22+Z23+Z24+Z25+Z26+Z27+Z28+Z29+Z30+Z31+Z32+Z33+Z34+Z35+Z36+Z37+Z38+Z39+Z40+Z41+Z42+Z43+Z44+Z45+Z46+Z47+Z48+Z49+Z50+Z51+Z52+Z53+Z54+Z55+Z56+Z57+Z58+Z59+Z60+Z61+Z62+Z63+Z64+Z65+Z66+Z67+Z68 -> 33880 | AH8: ='Lienzos y espejos'!AH8 -> Domingo | AI8: ='Lienzos y espejos'!AI8 -> Lunes | AJ8: ='Lienzos y espejos'!AJ8 -> Martes | AK8: ='Lienzos y espejos'!AK8 -> Miercoles | AL8: ='Lienzos y espejos'!AL8 -> Jueves | AM8: ='Lienzos y espejos'!AM8 -> Viernes | AN8: ='Lienzos y espejos'!AN8 -> Sabado | AP8: =SUM(AP9:AP59) -> 16190 | AQ8: =AQ9+AQ10+AQ11+AQ12+AQ13+AQ14+AQ15+AQ16+AQ17+AQ18+AQ19+AQ20+AQ21+AQ22+AQ23+AQ24+AQ25+AQ26+AQ27+AQ28+AQ29+AQ30+AQ31+AQ32+AQ33+AQ34+AQ35+AQ36+AQ37+AQ38+AQ39+AQ40+AQ41+AQ42+AQ43+AQ44+AQ45+AQ46+AQ47+AQ48+AQ49+AQ50+AQ51+AQ52+AQ53+AQ54+AQ55+AQ56+AQ57+AQ58+AQ59+AQ60+AQ61+AQ62+AQ63+AQ64+AQ65+AQ66+AQ67+AQ68+AQ69+AQ70+AQ71+AQ72+AQ73+AQ74+AQ75+AQ76+AQ77+AQ78+AQ79+AQ80+AQ81+AQ82+AQ83+AQ84+AQ85+AQ86+AQ87+AQ88+AQ89+AQ90+AQ91+AQ92+AQ93+AQ94+AQ95+AQ96+AQ97+AQ98+AQ99+AQ100+AQ101+AQ102+AQ103+AQ104+AQ105+AQ106+AQ107+AQ108+AQ109+AQ110+AQ111+AQ112+AQ113+AQ114+AQ115+AQ116+AQ117+AQ118+AQ119+AQ120+AQ121+AQ122+AQ123+AQ124+AQ125+AQ126+AQ127+AQ128+AQ129+AQ130+AQ131+AQ132+AQ133+AQ134+AQ135+AQ136+AQ137+AQ138+AQ139+AQ140+AQ141+AQ142+AQ143+AQ144+AQ145+AQ146+AQ147+AQ148+AQ149+AQ150+AQ151+AQ152+AQ153+AQ154+AQ155+AQ156+AQ157+AQ158+AQ159+AQ160+AQ161+AQ162+AQ163+AQ164+AQ165+AQ166+AQ167+AQ168+AQ169+AQ170+AQ171+AQ172+AQ173+AQ174+AQ175+AQ176+AQ177+AQ178+AQ179+AQ180+AQ181+AQ182+AQ183+AQ184+AQ185+AQ186+AQ187+AQ188+AQ189+AQ190+AQ191+AQ192+AQ193+AQ194+AQ195+AQ196+AQ197+AQ198+AQ199+AQ200+AQ201+AQ202+AQ203+AQ204+AQ205+AQ206+AQ207+AQ208+AQ209+AQ210+AQ211+AQ212+AQ213+AQ214+AQ215+AQ216+AQ217+AQ218+AQ219+AQ220+AQ221+AQ222+AQ223+AQ224+AQ225+AQ226+AQ227+AQ228+AQ229+AQ230+AQ231+AQ232+AQ233+AQ234+AQ235+AQ236+AQ237+AQ238+AQ239+AQ240+AQ241+AQ242+AQ243+AQ244+AQ245+AQ246+AQ247+AQ248+AQ249+AQ250+AQ251+AQ252+AQ253+AQ254+AQ255+AQ256+AQ257+AQ258+AQ259+AQ260+AQ261+AQ262+AQ263+AQ264+AQ265+AQ266+AQ267+AQ268+AQ269+AQ270+AQ271+AQ272+AQ273+AQ274+AQ275+AQ276+AQ277+AQ278+AQ279+AQ280+AQ281+AQ282+AQ283+AQ284+AQ285+AQ286+AQ287+AQ288+AQ289+AQ290+AQ291+AQ292+AQ293+AQ294+AQ295+AQ296+AQ297+AQ298+AQ299+AQ300+AQ301+AQ302+AQ303+AQ304+AQ305+AQ306+AQ307+AQ308+AQ309+AQ310+AQ311+AQ312+AQ313+AQ314+AQ315+AQ316+AQ317+AQ318+AQ319+AQ320+AQ321+AQ322+AQ323+AQ324+AQ325+AQ326+AQ327+AQ328+AQ329+AQ330+AQ331+AQ332+AQ333+AQ334+AQ335+AQ336+AQ337+AQ338+AQ339+AQ340+AQ341+AQ342+AQ343+AQ344+AQ345+AQ346+AQ347+AQ348+AQ349+AQ350+AQ351+AQ352+AQ353+AQ354+AQ355+AQ356+AQ357+AQ358+AQ359+AQ360+AQ361+AQ362+AQ363+AQ364+AQ365+AQ366+AQ367+AQ368+AQ369+AQ370+AQ371+AQ372+AQ373+AQ374+AQ375+AQ376+AQ377+AQ378+AQ379+AQ380+AQ381+AQ382+AQ383+AQ384+AQ385+AQ386+AQ387+AQ388+AQ389+AQ390+AQ391+AQ392+AQ393+AQ394+AQ395+AQ396+AQ397+AQ398+AQ399+AQ400+AQ401+AQ402+AQ403+AQ404+AQ405+AQ406+AQ407+AQ408+AQ409+AQ410+AQ411+AQ412+AQ413+AQ414+AQ415+AQ416+AQ417+AQ418+AQ419+AQ420+AQ421+AQ422+AQ423+AQ424+AQ425+AQ426+AQ427+AQ428+AQ429+AQ430+AQ431+AQ432+AQ433+AQ434+AQ435+AQ436+AQ437+AQ438+AQ439+AQ440+AQ441+AQ442+AQ443+AQ444+AQ445+AQ446+AQ447+AQ448+AQ449+AQ450+AQ451+AQ452+AQ453+AQ454+AQ455+AQ456+AQ457+AQ458+AQ459+AQ460+AQ461+AQ462+AQ463+AQ464+AQ465+AQ466+AQ467+AQ468+AQ469+AQ470+AQ471+AQ472+AQ473+AQ474+AQ475+AQ476+AQ477+AQ478+AQ479+AQ480+AQ481+AQ482+AQ483+AQ484+AQ485+AQ486+AQ487+AQ488+AQ489+AQ490+AQ491+AQ492+AQ493+AQ494+AQ495+AQ496+AQ497+AQ498+AQ499+AQ500+AQ501+AQ502+AQ503+AQ504+AQ505+AQ506+AQ507+AQ508+AQ509+AQ510+AQ511+AQ512+AQ513+AQ514+AQ515+AQ516+AQ517+AQ518+AQ519+AQ520+AQ521+AQ522+AQ523+AQ524+AQ525+AQ526+AQ527+AQ528+AQ529+AQ530+AQ531+AQ532+AQ533+AQ534+AQ535+AQ536+AQ537+AQ538+AQ539+AQ540+AQ541+AQ542+AQ543+AQ544+AQ545+AQ546+AQ547+AQ548+AQ549+AQ550+AQ551+AQ552+AQ553 -> 22200 | AR8: =AQ8-AP8 -> 6010 | AS8: =AS9+AS10+AS11+AS12+AS13+AS14+AS15+AS16+AS17+AS18+AS19+AS20+AS21+AS22+AS23+AS24+AS25+AS26+AS27+AS28+AS29+AS30+AS31+AS32+AS33+AS34+AS35+AS36+AS37+AS38+AS39+AS40+AS41+AS42+AS43+AS44+AS45+AS46+AS47+AS48+AS49+AS50+AS51+AS52+AS53+AS54+AS55+AS56+AS57+AS58+AS59+AS60+AS61+AS62+AS63+AS64+AS65+AS66+AS67+AS68+AS69+AS70+AS71+AS72+AS73+AS74+AS75+AS76+AS77+AS78+AS79+AS80+AS81+AS82+AS83+AS84+AS85+AS86+AS87+AS88+AS89+AS90+AS91+AS92+AS93+AS94+AS95+AS96+AS97+AS98+AS99+AS100+AS102+AS103+AS104+AS105+AS106+AS107+AS108+AS109+AS110+AS111+AS112+AS113+AS114+AS115+AS116+AS117+AS118+AS119+AS120+AS121+AS122+AS123+AS124+AS125+AS126+AS127+AS128+AS129+AS131+AS132+AS133+AS134+AS135+AS136+AS137+AS138+AS139+AS140+AS141+AS142+AS143+AS144+AS145+AS146+AS147+AS148+AS149+AS150+AS151+AS152+AS153+AS154+AS155+AS156+AS157+AS158+AS159+AS160+AS161+AS162+AS163+AS164+AS165+AS166+AS167+AS168+AS169+AS170+AS171+AS172+AS173+AS174+AS175+AS176+AS177+AS178+AS179+AS180+AS181+AS182+AS183+AS184+AS185+AS186+AS187+AS188+AS189+AS190+AS191+AS192+AS193+AS194+AS195+AS196+AS197+AS198+AS199+AS200+AS201+AS202+AS204+AS205+AS206+AS207+AS208+AS209+AS210+AS211+AS212+AS213+AS214+AS215+AS217+AS218+AS219+AS220+AS221+AS222+AS223+AS224+AS225+AS226+AS227+AS228+AS229+AS230+AS231+AS232+AS233+AS234+AS235+AS236+AS237+AS238+AS240+AS241+AS242+AS243+AS244+AS245+AS246+AS247+AS248+AS249+AS250+AS251+AS252+AS253+AS254+AS255+AS256+AS257+AS258+AS259+AS260+AS261+AS262+AS263+AS264+AS266+AS267+AS268+AS269+AS270+AS271+AS272+AS273+AS276+AS277+AS278+AS279+AS280+AS281+AS283+AS284+AS285+AS286+AS287+AS288+AS289+AS290+AS291+AS292+AS293+AS294+AS295+AS296+AS297+AS298+AS299+AS300+AS301+AS302+AS303+AS304+AS305+AS306+AS307+AS308+AS309+AS310+AS311+AS312+AS313+AS314+AS315+AS316+AS317+AS318+AS319+AS320+AS321+AS322+AS323+AS324+AS325+AS326+AS327+AS328+AS329+AS330+AS331+AS332+AS333+AS334+AS335+AS336+AS337+AS338+AS339+AS340+AS341+AS342+AS343+AS344+AS345+AS346+AS347+AS348+AS349+AS350+AS351+AS352+AS353+AS354+AS355+AS356+AS357+AS358+AS359+AS360+AS361+AS362+AS363+AS364+AS366+AS367+AS368+AS369+AS370+AS371+AS372+AS373+AS374+AS375+AS376+AS377+AS378+AS379+AS380+AS381+AS382+AS383+AS384+AS385+AS386+AS387+AS388+AS389+AS390+AS391+AS392+AS393+AS394+AS395+AS396+AS397+AS398+AS399+AS400+AS401+AS402+AS403+AS404+AS405+AS406+AS407+AS408+AS409+AS410+AS411+AS412+AS413+AS414+AS415+AS416+AS417+AS419+AS420+AS421+AS422+AS423+AS424+AS425+AS426+AS427+AS428+AS429+AS430+AS431+AS432+AS433+AS434+AS435+AS436+AS437+AS438+AS439+AS440+AS441+AS442+AS443+AS444+AS445+AS446+AS447+AS448+AS449+AS450+AS451+AS452+AS453+AS454+AS455+AS456+AS457+AS458+AS459+AS460+AS461+AS462+AS463+AS464+AS465+AS466+AS467+AS468+AS469+AS470+AS471 -> 86240
